System.InvalidOperationException: The instance of entity type 'Contact' cannot be tracked because another instance with the same key value for {'ContactId'} is already being tracked. When attaching existing entities, ensure that only one entity instance with a given key value is attached. Consider using 'DbContextOptionsBuilder.EnableSensitiveDataLogging' to see the conflicting key values.
   at Microsoft.EntityFrameworkCore.ChangeTracking.Internal.IdentityMap`1.ThrowIdentityConflict(InternalEntityEntry entry)
   at Microsoft.EntityFrameworkCore.ChangeTracking.Internal.IdentityMap`1.Add(TKey key, InternalEntityEntry entry, Boolean updateDuplicate)
   at Microsoft.EntityFrameworkCore.ChangeTracking.Internal.IdentityMap`1.Add(TKey key, InternalEntityEntry entry)
   at Microsoft.EntityFrameworkCore.ChangeTracking.Internal.IdentityMap`1.Add(InternalEntityEntry entry)
   at Microsoft.EntityFrameworkCore.ChangeTracking.Internal.StateManager.StartTracking(InternalEntityEntry entry)
   at Microsoft.EntityFrameworkCore.ChangeTracking.Internal.InternalEntityEntry.SetEntityState(EntityState oldState, EntityState newState, Boolean acceptChanges, Boolean modifyProperties)
   at Microsoft.EntityFrameworkCore.ChangeTracking.Internal.InternalEntityEntry.SetEntityState(EntityState entityState, Boolean acceptChanges, Boolean modifyProperties, Nullable`1 forceStateWhenUnknownKey)
   at Microsoft.EntityFrameworkCore.ChangeTracking.Internal.EntityGraphAttacher.PaintAction(EntityEntryGraphNode`1 node)
   at Microsoft.EntityFrameworkCore.ChangeTracking.Internal.EntityEntryGraphIterator.TraverseGraph[TState](EntityEntryGraphNode`1 node, Func`2 handleNode)
   at Microsoft.EntityFrameworkCore.ChangeTracking.Internal.EntityGraphAttacher.AttachGraph(InternalEntityEntry rootEntry, EntityState targetState, EntityState storeGeneratedWithKeySetTargetState, Boolean forceStateWhenUnknownKey)
   at Microsoft.EntityFrameworkCore.DbContext.SetEntityState(InternalEntityEntry entry, EntityState entityState)
   at Microsoft.EntityFrameworkCore.DbContext.Remove[TEntity](TEntity entity)
   at Microsoft.EntityFrameworkCore.Internal.InternalDbSet`1.Remove(TEntity entity)
   at Contacts.Data.Sqlite.SqliteDataStore.DeleteContact(Contact contact) in /Users/jguadagno/Projects/Contacts/src/Contacts.Data.Sqlite/SqliteDataStore.cs:line 88
   at Contacts.Data.ContactRepository.DeleteContact(Contact contact) in /Users/jguadagno/Projects/Contacts/src/Contacts.Data/ContactRepository.cs:line 45
   at Contacts.Logic.ContactManager.DeleteContact(Contact contact) in /Users/jguadagno/Projects/Contacts/src/Contacts.Logic/ContactManager.cs:line 100
   at Contacts.Logic.ContactManager.DeleteContact(Int32 contactId) in /Users/jguadagno/Projects/Contacts/src/Contacts.Logic/ContactManager.cs:line 89
   at Contacts.Api.Controllers.ContactsController.DeleteContact(Int32 id) in /Users/jguadagno/Projects/Contacts/src/Contacts.Api/Controllers/ContactsController.cs:line 46
   at lambda_method(Closure , Object , Object[] )
   at Microsoft.Extensions.Internal.ObjectMethodExecutor.Execute(Object target, Object[] parameters)
   at Microsoft.AspNetCore.Mvc.Infrastructure.ActionMethodExecutor.SyncObjectResultExecutor.Execute(IActionResultTypeMapper mapper, ObjectMethodExecutor executor, Object controller, Object[] arguments)
   at Microsoft.AspNetCore.Mvc.Infrastructure.ControllerActionInvoker.InvokeActionMethodAsync()
   at Microsoft.AspNetCore.Mvc.Infrastructure.ControllerActionInvoker.Next(State& next, Scope& scope, Object& state, Boolean& isCompleted)
   at Microsoft.AspNetCore.Mvc.Infrastructure.ControllerActionInvoker.InvokeNextActionFilterAsync()
--- End of stack trace from previous location where exception was thrown ---
   at Microsoft.AspNetCore.Mvc.Infrastructure.ControllerActionInvoker.Rethrow(ActionExecutedContextSealed context)
   at Microsoft.AspNetCore.Mvc.Infrastructure.ControllerActionInvoker.Next(State& next, Scope& scope, Object& state, Boolean& isCompleted)
   at Microsoft.AspNetCore.Mvc.Infrastructure.ControllerActionInvoker.InvokeInnerFilterAsync()
--- End of stack trace from previous location where exception was thrown ---
   at Microsoft.AspNetCore.Mvc.Infrastructure.ResourceInvoker.<InvokeFilterPipelineAsync>g__Awaited|19_0(ResourceInvoker invoker, Task lastTask, State next, Scope scope, Object state, Boolean isCompleted)
   at Microsoft.AspNetCore.Mvc.Infrastructure.ResourceInvoker.<InvokeAsync>g__Awaited|17_0(ResourceInvoker invoker, Task task, IDisposable scope)
   at Microsoft.AspNetCore.Routing.EndpointMiddleware.<Invoke>g__AwaitRequestTask|6_0(Endpoint endpoint, Task requestTask, ILogger logger)
   at Microsoft.AspNetCore.Authorization.AuthorizationMiddleware.Invoke(HttpContext context)
   at Microsoft.AspNetCore.Diagnostics.DeveloperExceptionPageMiddleware.Invoke(HttpContext context)

HEADERS
=======
Connection: Keep-Alive
Accept-Encoding: gzip,deflate
Host: localhost:5001
User-Agent: Apache-HttpClient/4.5.12 (Java/11.0.7)
